<?xml version="1.0"?>
<robot name="integracio3_1" xmlns:xacro="http://www.ros.org/wiki/xacro">

	<link name="anchor">
		<visual>
			<origin xyz="0 0 0" rpy="0 0 0"/>
			<geometry>
				<box size="0.01 0.01 0.01"/>
			</geometry>
		</visual>

		<collision>
			<origin xyz="0 0 0" rpy="0 0 0"/>
			<geometry>
				<box size="0.01 0.01 0.01"/>
			</geometry>
		</collision>

		<inertial>
			<origin xyz="0 0 0" rpy="0 0 0"/>
			<mass value="1000"/>
			<inertia ixx="100" ixy="0.0" ixz="0.0" iyy="100" iyz="0.0" izz="100"/>
		</inertial>
	</link>
	<gazebo reference="anchor">
		<static>true</static>
	</gazebo>

	<joint name="free_joint" type="continuous">
		<origin xyz="0 0 1.0" rpy="1.5708 0 0"/>
		<parent link="anchor"/>
		<child link="arm"/>
		<axis xyz="1 0 0"/>
		<limit effort="300" velocity="300" />
		<dynamics damping="0.03" friction="0.05"/>
	</joint>

	<link name="arm">
		<visual>
			<origin xyz="0 0 0.105" rpy="0 0 0"/>
			<geometry>
				<box size="0.005 0.003 0.21"/>
			</geometry>
			<material name="blue">
				<color rgba="0.24 0.06 0.03 1"/>
			</material>
		</visual>

		<collision>
			<origin xyz="0 0 0.105" rpy="0 0 0"/>
			<geometry>
				<box size="0.005 0.003 0.21"/>
			</geometry>
		</collision>

		<inertial>
			<origin xyz="0 0 0.105" rpy="0 0 0"/>
			<mass value="0.001"/>
			<inertia ixx="0.0001" ixy="0.0" ixz="0.0" iyy="0.0001" iyz="0.0" izz="0.0001"/>
		</inertial>
	</link>

	<joint name="motor_joint" type="continuous">
		<origin xyz="0 0.0015 0.21" rpy="0 0 0"/>
		<parent link="arm"/>
		<child link="helix"/>
		<axis xyz="0 1 0"/>
		<limit effort="500" velocity="255"/>
		<dynamics damping="0.01" friction="0.1"/>
	</joint>



	<!-- we need to add a transmission with this joint so the gazebo ros control plugin can see it in gazebo -->
	<transmission name="free_joint_trans">
		<type>transmission_interface/SimpleTransmission</type>
		<joint name="free_joint">
			<hardwareInterface>hardware_interface/EffortJointInterface</hardwareInterface>
		</joint>
		<actuator name="bearings">
			<mechanicalReduction>1</mechanicalReduction>
		</actuator>
	</transmission>

	<transmission name="motor_joint_trans">
		<type>transmission_interface/SimpleTransmission</type>
		<joint name="motor_joint">
			<hardwareInterface>hardware_interface/VelocityJointInterface</hardwareInterface>
		</joint>
		<actuator name="motor">
			<mechanicalReduction>1</mechanicalReduction>
		</actuator>
	</transmission>

</robot>
